Workbook

Sheet (BAD)Data analyized
A1: 0.05 | F1: 0.05 | K1: 0.05 | P1: 0.05 | U1: 0.1 | Z1: 0.1 | AE1: 0.1 | AJ1: 0.1 | AO1: 0.1 | AT1: 0.1 | AY1: 0.15 | BD1: 0.15 | BI1: 0.15 | BN1: 0.15 | BS1: 0.15 | BX1: 0.15 | CC1: 0.2 | CH1: 0.2 | CM1: 0.2 | CR1: 0.2 | CW1: 0.25 | DB1: 0.25 | DG1: 0.25 | DL1: 0.25 | DQ1: 0.3 | DV1: 0.3 | EA1: 0.3 | EF1: 0.3 | EK1: 0.3 | EP1: 0.3 | EU1: 0.3 | EZ1: 0.3 | FE1: 0.35 | FJ1: 0.35 | FO1: 0.35 | FT1: 0.35 | FY1: 0.4 | GD1: 0.4 | GI1: 0.4 | GN1: 0.4 | GS1: 0.45 | GX1: 0.45 | HC1: 0.45 | HH1: 0.45 | HM1: 0.5 | HR1: 0.5 | HW1: 0.5 | IB1: 0.5 | IG1: 0.5 | IL1: 0.5 | IQ1: 0.5 | IV1: 0.5
A2: Cell 13 Timestamp | B2: 5pct Cell 13 Current | C2: 5pct Cell 13 Voltage | D2: 5pct Cell 13 Temp | E2: Cell 13 Resistance | F2: Cell 14 Timestamp | G2: 5pct Cell 14 Current | H2: 5pct Cell 14 Voltage | I2: 5pct Cell 14 Temp | J2: Cell 14 Resistance | K2: Cell 15 Timestamp | L2: 5pct Cell 15 Current | M2: 5pct Cell 15 Voltage | N2: 5pct Cell 15 Temp | O2: Cell 15 Resistance | P2: Cell 16 Timestamp | Q2: 5pct Cell 16 Current | R2: 5pct Cell 16 Voltage | S2: 5pct Cell 16 Temp | T2: Cell 16 Resistance | U2: Cell 11 Timestamp | V2: 10pct Cell 11 Current | W2: 10pct Cell 11 Voltage | X2: 10pct Cell 11 Temp | Y2: Cell 11 Resistance | Z2: Cell 12 Timestamp | AA2: 10pct Cell 12 Current | AB2: 10pct Cell 12 Voltage | AC2: 10pct Cell 12 Temp | AD2: Cell 12 Resistance | AE2: Cell 13 Timestamp | AF2: 10pct Cell 13 Current | AG2: 10pct Cell 13 Voltage | AH2: 10pct Cell 13 Temp | AI2: Cell 13 Resistance | AJ2: Cell 14 Timestamp | AK2: 10pct Cell 14 Current | AL2: 10pct Cell 14 Voltage | AM2: 10pct Cell 14 Temp | AN2: Cell 14 Resistance | AO2: Cell 15 Timestamp | AP2: 10pct Cell 15 Current | AQ2: 10pct Cell 15 Voltage | AR2: 10pct Cell 15 Temp | AS2: Cell 15 Resistance | AT2: Cell 16 Timestamp | AU2: 10pct Cell 16 Current | AV2: 10pct Cell 16 Voltage | AW2: 10pct Cell 16 Temp | AX2: Cell 16 Resistance | AY2: Cell 9 Timestamp | AZ2: 15pct Cell 9 Current | BA2: 15pct Cell 9 Voltage | BB2: 15pct Cell 9 Temp | BC2: Cell 9 Resistance | BD2: Cell 10 Timestamp | BE2: 15pct Cell 10 Current | BF2: 15pct Cell 10 Voltage | BG2: 15pct Cell 10 Temp | BH2: Cell 10 Resistance | BI2: Cell 11 Timestamp | BJ2: 15pct Cell 11 Current | BK2: 15pct Cell 11 Voltage | BL2: 15pct Cell 11 Temp | BM2: Cell 11 Resistance | BN2: Cell 12 Timestamp | BO2: 15pct Cell 12 Current | BP2: 15pct Cell 12 Voltage | BQ2: 15pct Cell 12 Temp | BR2: Cell 12 Resistance | BS2: Cell 9 Timestamp | BT2: 15pct Cell 9 Current | BU2: 15pct Cell 9 Voltage | BV2: 15pct Cell 9 Temp | BW2: Cell 9 Resistance | BX2: Cell 10 Timestamp | BY2: 15pct Cell 10 Current | BZ2: 15pct Cell 10 Voltage | CA2: 15pct Cell 10 Temp | CB2: Cell 10 Resistance | CC2: Cell 5 Timestamp | CD2: 20pct Cell 5 Current | CE2: 20pct Cell 5 Voltage | CF2: 20pct Cell 5 Temp | CG2: Cell 5 Resistance | CH2: Cell 6 Timestamp | CI2: 20pct Cell 6 Current | CJ2: 20pct Cell 6 Voltage | CK2: 20pct Cell 6 Temp | CL2: Cell 6 Resistance | CM2: Cell 7 Timestamp | CN2: 20pct Cell 7 Current | CO2: 20pct Cell 7 Voltage | CP2: 20pct Cell 7 Temp | CQ2: Cell 7 Resistance | CR2: Cell 8 Timestamp | CS2: 20pct Cell 8 Current | CT2: 20pct Cell 8 Voltage | CU2: 20pct Cell 8 Temp | CV2: Cell 8 Resistance | CW2: Cell 1 Timestamp | CX2: 25pct Cell 1 Current | CY2: 25pct Cell 1 Voltage | CZ2: 25pct Cell 1 Temp | DA2: Cell 1 Resistance | DB2: Cell 2 Timestamp | DC2: 25pct Cell 2 Current | DD2: 25pct Cell 2 Voltage | DE2: 25pct Cell 2 Temp | DF2: Cell 2 Resistance | DG2: Cell 3 Timestamp | DH2: 25pct Cell 3 Current | DI2: 25pct Cell 3 Voltage | DJ2: 25pct Cell 3 Temp | DK2: Cell 3 Resistance | DL2: Cell 4 Timestamp | DM2: 25pct Cell 4 Current | DN2: 25pct Cell 4 Voltage | DO2: 25pct Cell 4 Temp | DP2: 25pct Cell 4 Resistance | DQ2: 30pct Cell 9 Timestamp | DR2: 30pct Cell 9 Current | DS2: 30pct Cell 9 Voltage | DT2: 30pct Cell 9 Temp | DU2: 30pct Cell 9 Resistance | DV2: Cell 10 Timestamp | DW2: 30pct Cell 10 Current | DX2: 30pct Cell 10 Voltage | DY2: 30pct Cell 10 Temp | DZ2: Cell 10 Resistance | EA2: Cell 11 Timestamp | EB2: 30pct Cell 11 Current | EC2: 30pct Cell 11 Voltage | ED2: 30pct Cell 11 Temp | EE2: Cell 11 Resistance | EF2: Cell 12 Timestamp | EG2: 30pct Cell 12 Current | EH2: 30pct Cell 12 Voltage | EI2: 30pct Cell 12 Temp | EJ2: Cell 12 Resistance | EK2: 30pct Cell 13 Timestamp | EL2: 30pct Cell 13 Current | EM2: 30pct Cell 13 Voltage | EN2: 30pct Cell 13 Temp | EO2: Cell 13 Resistance | EP2: Cell 14 Timestamp | EQ2: 30pct Cell 14 Current | ER2: 30pct Cell 14 Voltage | ES2: 30pct Cell 14 Temp | ET2: Cell 14 Resistance | EU2: Cell 15 Timestamp | EV2: 30pct Cell 15 Current | EW2: 30pct Cell 15 Voltage | EX2: 30pct Cell 15 Temp | EY2: Cell 15 Resistance | EZ2: Cell 16 Timestamp | FA2: 30pct Cell 16 Current | FB2: 30pct Cell 16 Voltage | FC2: 30pct Cell 16 Temp | FD2: Cell 16 Resistance | FE2: 35pct Cell 9 Timestamp | FF2: 35pct Cell 9 Current | FG2: 35pct Cell 9 Voltage | FH2: 35pct Cell 9 Temp | FI2: Cell 9 Resistance | FJ2: Cell 10 Timestamp | FK2: 35pct Cell 10 Current | FL2: 35pct Cell 10 Voltage | FM2: 35pct Cell 10 Temp | FN2: Cell 10 Resistance | FO2: Cell 11 Timestamp | FP2: 35pct Cell 11 Current | FQ2: 35pct Cell 11 Voltage | FR2: 35pct Cell 11 Temp | FS2: Cell 11 Resistance | FT2: 35pct Cell 12 Timestamp | FU2: 35pct Cell 12 Current | FV2: 35pct Cell 12 Voltage | FW2: 35pct Cell 12 Temp | FX2: Cell 12 Resistance | FY2: Cell 5 Timestamp | FZ2: 40pct Cell 5 Current | GA2: 40pct Cell 5 Voltage | GB2: 40pct Cell 5 Temp | GC2: Cell 5 Resistance | GD2: Cell 6 Timestamp | GE2: 40pct Cell 6 Current | GF2: 40pct Cell 6 Voltage | GG2: 40pct Cell 6 Temp | GH2: Cell 6 Resistance | GI2: Cell 7 Timestamp | GJ2: 40pct Cell 7 Current | GK2: 40pct Cell 7 Voltage | GL2: 40pct Cell 7 Temp | GM2: Cell 7 Resistance | GN2: Cell 8 Timestamp | GO2: 40pct Cell 8 Current | GP2: 40pct Cell 8 Voltage | GQ2: 40pct Cell 8 Temp | GR2: Cell 8 Resistance | GS2: Cell 1 Timestamp | GT2: 45pct Cell 1 Current | GU2: 45pct Cell 1 Voltage | GV2: 45pct Cell 1 Temp | GW2: Cell 1 Resistance | GX2: Cell 2 Timestamp | GY2: 45pct Cell 2 Current | GZ2: 45pct Cell 2 Voltage | HA2: 45pct Cell 2 Temp | HB2: Cell 2 Resistance | HC2: Cell 3 Timestamp | HD2: 45pct Cell 3 Current | HE2: 45pct Cell 3 Voltage | HF2: 45pct Cell 3 Temp | HG2: Cell 3 Resistance | HH2: Cell 4 Timestamp | HI2: 45pct Cell 4 Current | HJ2: 45pct Cell 4 Voltage | HK2: 45pct Cell 4 Temp | HL2: 45pct Cell 4 Resistance | HM2: Cell 9 Timestamp | HN2: 50pct Cell 9 Current | HO2: 50pct Cell 9 Voltage | HP2: 50pct Cell 9 Temp | HQ2: Cell 9 Resistance | HR2: Cell 10 Timestamp | HS2: 50pct Cell 10 Current | HT2: 50pct Cell 10 Voltage | HU2: 50pct Cell 10 Temp | HV2: Cell 10 Resistance | HW2: Cell 11 Timestamp | HX2: 50pct Cell 11 Current | HY2: 50pct Cell 11 Voltage | HZ2: 50pct Cell 11 Temp | IA2: Cell 11 Resistance | IB2: Cell 12 Timestamp | IC2: 50pct Cell 12 Current | ID2: 50pct Cell 12 Voltage | IE2: 50pct Cell 12 Temp | IF2: Cell 12 Resistance | IG2: Cell 13 Timestamp | IH2: 50pct Cell 13 Current | II2: 50pct Cell 13 Voltage | IJ2: 50pct Cell 13 Temp | IK2: Cell 13 Resistance | IL2: Cell 14 Timestamp | IM2: 50pct Cell 14 Current | IN2: 50pct Cell 14 Voltage | IO2: 50pct Cell 14 Temp | IP2: Cell 14 Resistance | IQ2: Cell 15 Timestamp | IR2: 50pct Cell 15 Current | IS2: 50pct Cell 15 Voltage | IT2: 50pct Cell 15 Temp | IU2: Cell 15 Resistance | IV2: Cell 16 Timestamp | IW2: 50pct Cell 16 Current | IX2: 50pct Cell 16 Voltage | IY2: 50pct Cell 16 Temp | IZ2: Cell 16 Resistance
A3: 10-24-2025-Fri 18-46-37-PM | B3: -0.2 | C3: 5.848 | D3: -54.6468 | E3: -36.55 | F3: 10-24-2025-Fri 18-46-37-PM | G3: 0.2 | H3: 5.864 | I3: -51.927 | J3: 36.65 | K3: 10-24-2025-Fri 18-46-37-PM | L3: 0.2 | M3: 5.848 | N3: -54.4818 | O3: 36.55 | P3: 10-24-2025-Fri 18-46-37-PM | Q3: 0.1 | R3: 5.856 | S3: -53.343 | T3: 73.2 | U3: 10-24-2025-Fri 18-46-37-PM | V3: 0.1 | W3: 5.856 | X3: -56.2626 | Y3: 73.2 | Z3: 10-24-2025-Fri 18-46-37-PM | AA3: 0.2 | AB3: 5.86 | AC3: -52.642 | AD3: 36.625 | AE3: 09-12-2025-Fri 12-24-42-PM | AF3: 0.2 | AG3: 5.944 | AH3: -50.5862 | AI3: 37.15 | AJ3: 09-12-2025-Fri 12-24-42-PM | AK3: 0 | AL3: 5.96 | AM3: -50.024 | AN3: inf | AO3: 09-12-2025-Fri 12-24-42-PM | AP3: 0.1 | AQ3: 5.948 | AR3: -50.5202 | AS3: 74.35 | AT3: 09-12-2025-Fri 12-24-42-PM | AU3: 0.2 | AV3: 5.952 | AW3: -50.372 | AX3: 37.2 | AY3: 09-12-2025-Fri 12-24-42-PM | AZ3: 0.1 | BA3: 5.944 | BB3: -52.8979 | BC3: 74.3 | BD3: 09-12-2025-Fri 12-24-42-PM | BE3: 0.3 | BF3: 5.952 | BG3: -51.313 | BH3: 24.8 | BI3: 09-12-2025-Fri 12-24-42-PM | BJ3: 0.1 | BK3: 5.952 | BL3: -51.2799 | BM3: 74.4 | BN3: 09-12-2025-Fri 12-24-42-PM | BO3: 0.4 | BP3: 5.952 | BQ3: -50.09 | BR3: 18.6 | BS3: 10-24-2025-Fri 18-46-37-PM | BT3: 0.3 | BU3: 5.848 | BV3: -58.3719 | BW3: 24.3667 | BX3: 10-24-2025-Fri 18-46-37-PM | BY3: 0.2 | BZ3: 5.86 | CA3: -54.809 | CB3: 36.625 | CR3: 10-24-2025-Fri 18-46-37-PM | CS3: 0.3 | CT3: 5.856 | CU3: -52.2046 | CV3: 24.4 | CW3: 10-24-2025-Fri 18-46-37-PM | CX3: 0.1 | CY3: 5.848 | CZ3: -54.083 | DA3: 73.1 | DQ3: 09-05-2025-Fri 20-13-43-PM | DR3: 0.1 | DS3: 5.904 | DT3: -64.5911 | DU3: 73.8 | DV3: 09-05-2025-Fri 20-13-43-PM | DW3: 0.4 | DX3: 5.912 | DY3: -63.166 | DZ3: 18.475 | EA3: 09-05-2025-Fri 20-13-43-PM | EB3: 0.2 | EC3: 5.912 | ED3: -63.2432 | EE3: 36.95 | EF3: 09-05-2025-Fri 20-13-43-PM | EG3: 0.3 | EH3: 5.908 | EI3: -61.521 | EJ3: 24.6167 | EK3: 09-27-2025-Sat 13-27-36-PM | EL3: 0.1 | EM3: 5.956 | EN3: -64.9854 | EO3: 74.45 | EP3: 09-27-2025-Sat 13-27-36-PM | EQ3: 0.2 | ER3: 5.972 | ES3: -63.012 | ET3: 37.325 | EU3: 09-27-2025-Sat 13-27-36-PM | EV3: 0.2 | EW3: 5.96 | EX3: -63.7035 | EY3: 37.25 | EZ3: 09-27-2025-Sat 13-27-36-PM | FA3: 0 | FB3: 5.964 | FC3: -62.667 | FD3: inf | FE3: 09-27-2025-Sat 13-27-36-PM | FF3: 0.1 | FG3: 5.964 | FH3: -67.2519 | FI3: 74.55 | FJ3: 09-27-2025-Sat 13-27-36-PM | FK3: 0.1 | FL3: 5.968 | FM3: -64.239 | FN3: 74.6 | FO3: 09-27-2025-Sat 13-27-36-PM | FP3: 0.2 | FQ3: 5.968 | FR3: -65.544 | FS3: 37.3 | FT3: 09-27-2025-Sat 13-27-36-PM | FU3: 0.4 | FV3: 5.964 | FW3: -63.406 | FX3: 18.6375 | GI3: 09-27-2025-Sat 13-27-36-PM | GJ3: 0.3 | GK3: 5.968 | GL3: -61.894 | GM3: 24.8667 | GN3: 09-27-2025-Sat 13-27-36-PM | GO3: 0.4 | GP3: 5.968 | GQ3: -61.6314 | GR3: 18.65 | GS3: 09-27-2025-Sat 13-27-36-PM | GT3: 0.1 | GU3: 5.964 | GV3: -63.586 | GW3: 74.55 | HM3: 08-29-2025-Fri 15-30-24-PM | HN3: 0.1 | HO3: 5.908 | HP3: -70.2708 | HQ3: 73.85 | HR3: 08-29-2025-Fri 15-30-24-PM | HS3: 0.2 | HT3: 5.912 | HU3: -69.932 | HV3: 36.95 | HW3: 08-29-2025-Fri 15-30-24-PM | HX3: 0.3 | HY3: 5.916 | HZ3: -69.6148 | IA3: 24.65 | IB3: 08-29-2025-Fri 15-30-24-PM | IC3: 0.4 | ID3: 5.908 | IE3: -68.97 | IF3: 18.4625 | IG3: 08-29-2025-Fri 15-30-24-PM | IH3: 0.1 | II3: 5.904 | IJ3: -68.729 | IK3: 73.8 | IL3: 08-29-2025-Fri 15-30-24-PM | IM3: 0.2 | IN3: 5.916 | IO3: -69.013 | IP3: 36.975 | IV3: 08-29-2025-Fri 15-30-24-PM | IW3: 0.2 | IX3: 5.908 | IY3: -69.779 | IZ3: 36.925
A4: 10-24-2025-Fri 18-46-40-PM | B4: -0.1 | C4: 5.848 | D4: -54.6798 | E4: -73.1 | F4: 10-24-2025-Fri 18-46-40-PM | G4: 0.1 | H4: 5.86 | I4: -51.96 | J4: 73.25 | K4: 10-24-2025-Fri 18-46-40-PM | L4: 0.2 | M4: 5.848 | N4: -54.4818 | O4: 36.55 | P4: 10-24-2025-Fri 18-46-40-PM | Q4: -0.1 | R4: 5.852 | S4: -53.36 | T4: -73.15 | U4: 10-24-2025-Fri 18-46-40-PM | V4: 0 | W4: 5.86 | X4: -56.2626 | Y4: inf | Z4: 10-24-2025-Fri 18-46-40-PM | AA4: 0.2 | AB4: 5.856 | AC4: -52.675 | AD4: 36.6 | AE4: 09-12-2025-Fri 12-24-45-PM | AF4: 0.3 | AG4: 5.944 | AH4: -50.6192 | AI4: 24.7667 | AJ4: 09-12-2025-Fri 12-24-45-PM | AK4: 0.1 | AL4: 5.96 | AM4: -50.035 | AN4: 74.5 | AO4: 09-12-2025-Fri 12-24-45-PM | AP4: 0.2 | AQ4: 5.948 | AR4: -50.5202 | AS4: 37.175 | AT4: 09-12-2025-Fri 12-24-45-PM | AU4: 0.1 | AV4: 5.952 | AW4: -50.355 | AX4: 74.4 | AY4: 09-12-2025-Fri 12-24-45-PM | AZ4: 0.4 | BA4: 5.948 | BB4: -52.8649 | BC4: 18.5875 | BD4: 09-12-2025-Fri 12-24-45-PM | BE4: 0.4 | BF4: 5.952 | BG4: -51.313 | BH4: 18.6 | BI4: 09-12-2025-Fri 12-24-45-PM | BJ4: 0.2 | BK4: 5.956 | BL4: -51.2799 | BM4: 37.225 | BN4: 09-12-2025-Fri 12-24-45-PM | BO4: 0.2 | BP4: 5.952 | BQ4: -50.123 | BR4: 37.2 | BS4: 10-24-2025-Fri 18-46-40-PM | BT4: 0.3 | BU4: 5.852 | BV4: -58.3719 | BW4: 24.3833 | BX4: 10-24-2025-Fri 18-46-40-PM | BY4: -0.1 | BZ4: 5.86 | CA4: -54.842 | CB4: -73.25 | CR4: 10-24-2025-Fri 18-46-40-PM | CS4: 0.3 | CT4: 5.856 | CU4: -52.2375 | CV4: 24.4 | CW4: 10-24-2025-Fri 18-46-40-PM | CX4: 0.2 | CY4: 5.848 | CZ4: -54.132 | DA4: 36.55 | DQ4: 09-05-2025-Fri 20-14-23-PM | DR4: 0.4 | DS4: 5.904 | DT4: -65.4455 | DU4: 18.45 | DV4: 09-05-2025-Fri 20-14-23-PM | DW4: 0.3 | DX4: 5.912 | DY4: -63.846 | DZ4: 24.6333 | EA4: 09-05-2025-Fri 20-14-23-PM | EB4: 0.1 | EC4: 5.908 | ED4: -63.9337 | EE4: 73.85 | EF4: 09-05-2025-Fri 20-14-23-PM | EG4: 0.4 | EH4: 5.908 | EI4: -62.125 | EJ4: 18.4625 | EK4: 09-27-2025-Sat 13-27-38-PM | EL4: 0.1 | EM4: 5.96 | EN4: -65.0511 | EO4: 74.5 | EP4: 09-27-2025-Sat 13-27-38-PM | EQ4: 0.3 | ER4: 5.972 | ES4: -63.045 | ET4: 24.8833 | EU4: 09-27-2025-Sat 13-27-38-PM | EV4: 0.3 | EW4: 5.96 | EX4: -63.7035 | EY4: 24.8333 | EZ4: 09-27-2025-Sat 13-27-38-PM | FA4: 0.3 | FB4: 5.964 | FC4: -62.684 | FD4: 24.85 | FE4: 09-27-2025-Sat 13-27-38-PM | FF4: 0.3 | FG4: 5.956 | FH4: -67.2519 | FI4: 24.8167 | FJ4: 09-27-2025-Sat 13-27-38-PM | FK4: 0.2 | FL4: 5.968 | FM4: -64.25 | FN4: 37.3 | FO4: 09-27-2025-Sat 13-27-38-PM | FP4: 0 | FQ4: 5.968 | FR4: -65.544 | FS4: inf | FT4: 09-27-2025-Sat 13-27-38-PM | FU4: -0.1 | FV4: 5.968 | FW4: -63.417 | FX4: -74.6 | GI4: 09-27-2025-Sat 13-27-38-PM | GJ4: 0.3 | GK4: 5.968 | GL4: -61.916 | GM4: 24.8667 | GN4: 09-27-2025-Sat 13-27-38-PM | GO4: 0.2 | GP4: 5.968 | GQ4: -61.6643 | GR4: 37.3 | GS4: 09-27-2025-Sat 13-27-38-PM | GT4: 0.6 | GU4: 5.96 | GV4: -63.602 | GW4: 12.4167 | HM4: 08-29-2025-Fri 15-31-46-PM | HN4: 0.1 | HO4: 5.904 | HP4: -70.861 | HQ4: 73.8 | HR4: 08-29-2025-Fri 15-31-46-PM | HS4: 0.3 | HT4: 5.908 | HU4: -70.5 | HV4: 24.6167 | HW4: 08-29-2025-Fri 15-31-46-PM | HX4: 0.4 | HY4: 5.912 | HZ4: -70.2052 | IA4: 18.475 | IB4: 08-29-2025-Fri 15-31-46-PM | IC4: 0.5 | ID4: 5.908 | IE4: -69.593 | IF4: 14.77 | IG4: 08-29-2025-Fri 15-31-46-PM | IH4: 0.1 | II4: 5.9 | IJ4: -69.4179 | IK4: 73.75 | IL4: 08-29-2025-Fri 15-31-46-PM | IM4: 0.2 | IN4: 5.912 | IO4: -69.615 | IP4: 36.95 | IV4: 08-29-2025-Fri 15-31-46-PM | IW4: 0.3 | IX4: 5.908 | IY4: -70.353 | IZ4: 24.6167
A5: 10-24-2025-Fri 18-46-47-PM | B5: -0.1 | C5: 5.848 | D5: -54.7457 | E5: -73.1 | F5: 10-24-2025-Fri 18-46-47-PM | G5: -0.2 | H5: 5.86 | I5: -52.081 | J5: -36.625 | K5: 10-24-2025-Fri 18-46-47-PM | L5: -0.3 | M5: 5.848 | N5: -54.6137 | O5: -24.3667 | P5: 10-24-2025-Fri 18-46-47-PM | Q5: 0.1 | R5: 5.856 | S5: -53.492 | T5: 73.2 | U5: 10-24-2025-Fri 18-46-47-PM | V5: 0.1 | W5: 5.86 | X5: -56.3616 | Y5: 73.25 | Z5: 10-24-2025-Fri 18-46-47-PM | AA5: -0.3 | AB5: 5.856 | AC5: -52.774 | AD5: -24.4 | AE5: 09-12-2025-Fri 12-24-47-PM | AF5: 0.2 | AG5: 5.948 | AH5: -50.6192 | AI5: 37.175 | AJ5: 09-12-2025-Fri 12-24-47-PM | AK5: 0.3 | AL5: 5.964 | AM5: -50.046 | AN5: 24.85 | AO5: 09-12-2025-Fri 12-24-47-PM | AP5: 0.2 | AQ5: 5.944 | AR5: -50.5202 | AS5: 37.15 | AT5: 09-12-2025-Fri 12-24-47-PM | AU5: 0.3 | AV5: 5.952 | AW5: -50.372 | AX5: 24.8 | AY5: 09-12-2025-Fri 12-24-47-PM | AZ5: 0.2 | BA5: 5.948 | BB5: -52.8979 | BC5: 37.175 | BD5: 09-12-2025-Fri 12-24-47-PM | BE5: 0.3 | BF5: 5.956 | BG5: -51.335 | BH5: 24.8167 | BI5: 09-12-2025-Fri 12-24-47-PM | BJ5: 0.2 | BK5: 5.96 | BL5: -51.2799 | BM5: 37.25 | BN5: 09-12-2025-Fri 12-24-47-PM | BO5: 0.3 | BP5: 5.952 | BQ5: -50.167 | BR5: 24.8 | BS5: 10-24-2025-Fri 18-46-47-PM | BT5: 0.5 | BU5: 5.852 | BV5: -58.4048 | BW5: 14.63 | BX5: 10-24-2025-Fri 18-46-47-PM | BY5: 0.2 | BZ5: 5.856 | CA5: -54.941 | CB5: 36.6 | CR5: 10-24-2025-Fri 18-46-47-PM | CS5: 0.3 | CT5: 5.856 | CU5: -52.3696 | CV5: 24.4 | CW5: 10-24-2025-Fri 18-46-47-PM | CX5: 0.4 | CY5: 5.848 | CZ5: -54.231 | DA5: 18.275 | DQ5: 09-05-2025-Fri 20-14-25-PM | DR5: 0 | DS5: 5.9 | DT5: -65.5112 | DU5: inf | DV5: 09-05-2025-Fri 20-14-25-PM | DW5: 0.2 | DX5: 5.912 | DY5: -63.857 | DZ5: 36.95 | EA5: 09-05-2025-Fri 20-14-25-PM | EB5: 0.2 | EC5: 5.912 | ED5: -63.9666 | EE5: 36.95 | EF5: 09-05-2025-Fri 20-14-25-PM | EG5: 0.2 | EH5: 5.912 | EI5: -62.136 | EJ5: 36.95 | EK5: 09-27-2025-Sat 13-27-41-PM | EL5: 0.1 | EM5: 5.96 | EN5: -65.0511 | EO5: 74.5 | EP5: 09-27-2025-Sat 13-27-41-PM | EQ5: 0.2 | ER5: 5.972 | ES5: -63.078 | ET5: 37.325 | EU5: 09-27-2025-Sat 13-27-41-PM | EV5: 0.1 | EW5: 5.96 | EX5: -63.7364 | EY5: 74.5 | EZ5: 09-27-2025-Sat 13-27-41-PM | FA5: 0.1 | FB5: 5.964 | FC5: -62.717 | FD5: 74.55 | FE5: 09-27-2025-Sat 13-27-41-PM | FF5: 0.1 | FG5: 5.96 | FH5: -67.2847 | FI5: 74.5 | FJ5: 09-27-2025-Sat 13-27-41-PM | FK5: 0.1 | FL5: 5.968 | FM5: -64.293 | FN5: 74.6 | FO5: 09-27-2025-Sat 13-27-41-PM | FP5: 0.1 | FQ5: 5.964 | FR5: -65.5769 | FS5: 74.55 | FT5: 09-27-2025-Sat 13-27-41-PM | FU5: 0.1 | FV5: 5.964 | FW5: -63.439 | FX5: 74.55 | GI5: 09-27-2025-Sat 13-27-41-PM | GJ5: 0.2 | GK5: 5.968 | GL5: -61.96 | GM5: 37.3 | GN5: 09-27-2025-Sat 13-27-41-PM | GO5: 0.3 | GP5: 5.972 | GQ5: -61.6971 | GR5: 24.8833 | GS5: 09-27-2025-Sat 13-27-41-PM | GT5: 0.3 | GU5: 5.964 | GV5: -63.652 | GW5: 24.85 | HM5: 08-29-2025-Fri 15-31-49-PM | HN5: 0.2 | HO5: 5.908 | HP5: -70.861 | HQ5: 36.925 | HR5: 08-29-2025-Fri 15-31-49-PM | HS5: 0.3 | HT5: 5.908 | HU5: -70.533 | HV5: 24.6167 | HW5: 08-29-2025-Fri 15-31-49-PM | HX5: 0 | HY5: 5.908 | HZ5: -70.2052 | IA5: inf | IB5: 08-29-2025-Fri 15-31-49-PM | IC5: 0.3 | ID5: 5.908 | IE5: -69.626 | IF5: 24.6167 | IG5: 08-29-2025-Fri 15-31-49-PM | IH5: 0.7 | II5: 5.904 | IJ5: -69.4508 | IK5: 10.5429 | IL5: 08-29-2025-Fri 15-31-49-PM | IM5: 0.2 | IN5: 5.916 | IO5: -69.735 | IP5: 36.975 | IV5: 08-29-2025-Fri 15-31-49-PM | IW5: 0.1 | IX5: 5.908 | IY5: -70.484 | IZ5: 73.85
A6: 10-24-2025-Fri 18-46-49-PM | B6: 0.1 | C6: 5.848 | D6: -54.8447 | E6: 73.1 | F6: 10-24-2025-Fri 18-46-49-PM | G6: 0 | H6: 5.864 | I6: -52.125 | J6: inf | K6: 10-24-2025-Fri 18-46-49-PM | L6: 0 | M6: 5.848 | N6: -54.6137 | O6: inf | P6: 10-24-2025-Fri 18-46-49-PM | Q6: 0.2 | R6: 5.852 | S6: -53.508 | T6: 36.575 | U6: 10-24-2025-Fri 18-46-49-PM | V6: 0.1 | W6: 5.86 | X6: -56.3946 | Y6: 73.25 | Z6: 10-24-2025-Fri 18-46-49-PM | AA6: 0.1 | AB6: 5.852 | AC6: -52.829 | AD6: 73.15 | AE6: 09-12-2025-Fri 12-24-49-PM | AF6: -0.1 | AG6: 5.948 | AH6: -50.6192 | AI6: -74.35 | AJ6: 09-12-2025-Fri 12-24-49-PM | AK6: 0.2 | AL6: 5.964 | AM6: -50.057 | AN6: 37.275 | AO6: 09-12-2025-Fri 12-24-49-PM | AP6: 0.2 | AQ6: 5.948 | AR6: -50.5531 | AS6: 37.175 | AT6: 09-12-2025-Fri 12-24-49-PM | AU6: 0.2 | AV6: 5.952 | AW6: -50.388 | AX6: 37.2 | AY6: 09-12-2025-Fri 12-24-49-PM | AZ6: 0.2 | BA6: 5.948 | BB6: -52.8979 | BC6: 37.175 | BD6: 09-12-2025-Fri 12-24-49-PM | BE6: 0.5 | BF6: 5.956 | BG6: -51.335 | BH6: 14.89 | BI6: 09-12-2025-Fri 12-24-49-PM | BJ6: 0 | BK6: 5.96 | BL6: -51.2799 | BM6: inf | BN6: 09-12-2025-Fri 12-24-49-PM | BO6: 0.4 | BP6: 5.956 | BQ6: -50.156 | BR6: 18.6125 | BS6: 10-24-2025-Fri 18-46-49-PM | BT6: 0.4 | BU6: 5.852 | BV6: -58.4048 | BW6: 18.2875 | BX6: 10-24-2025-Fri 18-46-49-PM | BY6: 0.1 | BZ6: 5.856 | CA6: -54.952 | CB6: 73.2 | CR6: 10-24-2025-Fri 18-46-49-PM | CS6: 0.5 | CT6: 5.856 | CU6: -52.4027 | CV6: 14.64 | CW6: 10-24-2025-Fri 18-46-49-PM | CX6: 0.5 | CY6: 5.848 | CZ6: -54.231 | DA6: 14.62 | DQ6: 09-05-2025-Fri 20-14-28-PM | DR6: 0.1 | DS6: 5.904 | DT6: -65.544 | DU6: 73.8 | DV6: 09-05-2025-Fri 20-14-28-PM | DW6: 0.2 | DX6: 5.912 | DY6: -63.9 | DZ6: 36.95 | EA6: 09-05-2025-Fri 20-14-28-PM | EB6: 0.3 | EC6: 5.912 | ED6: -63.9993 | EE6: 24.6333 | EF6: 09-05-2025-Fri 20-14-28-PM | EG6: 0.2 | EH6: 5.908 | EI6: -62.157 | EJ6: 36.925 | EK6: 09-27-2025-Sat 13-27-43-PM | EL6: 0 | EM6: 5.956 | EN6: -65.084 | EO6: inf | EP6: 09-27-2025-Sat 13-27-43-PM | EQ6: 0.2 | ER6: 5.972 | ES6: -63.089 | ET6: 37.325 | EU6: 09-27-2025-Sat 13-27-43-PM | EV6: 0.1 | EW6: 5.96 | EX6: -63.7693 | EY6: 74.5 | EZ6: 09-27-2025-Sat 13-27-43-PM | FA6: 0.2 | FB6: 5.964 | FC6: -62.75 | FD6: 37.275 | FE6: 09-27-2025-Sat 13-27-43-PM | FF6: 0.1 | FG6: 5.96 | FH6: -67.3176 | FI6: 74.5 | FJ6: 09-27-2025-Sat 13-27-43-PM | FK6: 0.2 | FL6: 5.968 | FM6: -64.348 | FN6: 37.3 | FO6: 09-27-2025-Sat 13-27-43-PM | FP6: 0.2 | FQ6: 5.972 | FR6: -65.6098 | FS6: 37.325 | FT6: 09-27-2025-Sat 13-27-43-PM | FU6: 0.2 | FV6: 5.968 | FW6: -63.472 | FX6: 37.3 | GI6: 09-27-2025-Sat 13-27-43-PM | GJ6: 0 | GK6: 5.972 | GL6: -61.971 | GM6: inf | GN6: 09-27-2025-Sat 13-27-43-PM | GO6: 0.4 | GP6: 5.968 | GQ6: -61.7301 | GR6: 18.65 | GS6: 09-27-2025-Sat 13-27-43-PM | GT6: 0.3 | GU6: 5.96 | GV6: -63.718 | GW6: 24.8333 | HM6: 08-29-2025-Fri 15-31-51-PM | HN6: 0.4 | HO6: 5.904 | HP6: -70.861 | HQ6: 18.45 | HR6: 08-29-2025-Fri 15-31-51-PM | HS6: 0.5 | HT6: 5.912 | HU6: -70.522 | HV6: 14.78 | HW6: 08-29-2025-Fri 15-31-51-PM | HX6: 0.1 | HY6: 5.912 | HZ6: -70.2379 | IA6: 73.9 | IB6: 08-29-2025-Fri 15-31-51-PM | IC6: 0.2 | ID6: 5.912 | IE6: -69.669 | IF6: 36.95 | IG6: 08-29-2025-Fri 15-31-51-PM | IH6: 0.3 | II6: 5.9 | IJ6: -69.4836 | IK6: 24.5833 | IL6: 08-29-2025-Fri 15-31-51-PM | IM6: 0.3 | IN6: 5.916 | IO6: -69.636 | IP6: 24.65 | IV6: 08-29-2025-Fri 15-31-51-PM | IW6: 0.2 | IX6: 5.908 | IY6: -70.336 | IZ6: 36.925
A7: 10-24-2025-Fri 18-46-52-PM | B7: 0.2 | C7: 5.848 | D7: -54.8447 | E7: 36.55 | F7: 10-24-2025-Fri 18-46-52-PM | G7: 0.1 | H7: 5.86 | I7: -52.158 | J7: 73.25 | K7: 10-24-2025-Fri 18-46-52-PM | L7: 0.1 | M7: 5.848 | N7: -54.6798 | O7: 73.1 | P7: 10-24-2025-Fri 18-46-52-PM | Q7: 0.1 | R7: 5.852 | S7: -53.558 | T7: 73.15 | U7: 10-24-2025-Fri 18-46-52-PM | V7: 0.1 | W7: 5.856 | X7: -56.4275 | Y7: 73.2 | Z7: 10-24-2025-Fri 18-46-52-PM | AA7: 0.4 | AB7: 5.856 | AC7: -52.851 | AD7: 18.3 | AE7: 09-12-2025-Fri 12-24-52-PM | AF7: 0.1 | AG7: 5.944 | AH7: -50.6522 | AI7: 74.3 | AJ7: 09-12-2025-Fri 12-24-52-PM | AK7: 0.2 | AL7: 5.964 | AM7: -50.079 | AN7: 37.275 | AO7: 09-12-2025-Fri 12-24-52-PM | AP7: 0.4 | AQ7: 5.948 | AR7: -50.5531 | AS7: 18.5875 | AT7: 09-12-2025-Fri 12-24-52-PM | AU7: 0.4 | AV7: 5.956 | AW7: -50.404 | AX7: 18.6125 | AY7: 09-12-2025-Fri 12-24-52-PM | AZ7: 0.4 | BA7: 5.948 | BB7: -52.8979 | BC7: 18.5875 | BD7: 09-12-2025-Fri 12-24-52-PM | BE7: 0.2 | BF7: 5.956 | BG7: -51.357 | BH7: 37.225 | BI7: 09-12-2025-Fri 12-24-52-PM | BJ7: 0.2 | BK7: 5.96 | BL7: -51.3129 | BM7: 37.25 | BN7: 09-12-2025-Fri 12-24-52-PM | BO7: 0.3 | BP7: 5.956 | BQ7: -50.156 | BR7: 24.8167 | BS7: 10-24-2025-Fri 18-46-52-PM | BT7: 0.4 | BU7: 5.852 | BV7: -58.4378 | BW7: 18.2875 | BX7: 10-24-2025-Fri 18-46-52-PM | BY7: 0.1 | BZ7: 5.856 | CA7: -54.985 | CB7: 73.2 | CR7: 10-24-2025-Fri 18-46-52-PM | CS7: 0.4 | CT7: 5.856 | CU7: -52.4357 | CV7: 18.3 | CW7: 10-24-2025-Fri 18-46-52-PM | CX7: 0.5 | CY7: 5.852 | CZ7: -54.264 | DA7: 14.63 | DQ7: 09-05-2025-Fri 20-15-22-PM | DR7: 0.3 | DS7: 5.9 | DT7: -66.1682 | DU7: 24.5833 | DV7: 09-05-2025-Fri 20-15-22-PM | DW7: 0.3 | DX7: 5.912 | DY7: -64.525 | DZ7: 24.6333 | EA7: 09-05-2025-Fri 20-15-22-PM | EB7: 0.2 | EC7: 5.912 | ED7: -64.6239 | EE7: 36.95 | EF7: 09-05-2025-Fri 20-15-22-PM | EG7: 0.2 | EH7: 5.908 | EI7: -62.793 | EJ7: 36.925 | EK7: 09-27-2025-Sat 13-27-45-PM | EL7: 0.3 | EM7: 5.96 | EN7: -65.1169 | EO7: 24.8333 | EP7: 09-27-2025-Sat 13-27-45-PM | EQ7: 0.2 | ER7: 5.972 | ES7: -63.144 | ET7: 37.325 | EU7: 09-27-2025-Sat 13-27-45-PM | EV7: 0.2 | EW7: 5.956 | EX7: -63.8022 | EY7: 37.225 | EZ7: 09-27-2025-Sat 13-27-45-PM | FA7: 0 | FB7: 5.964 | FC7: -62.783 | FD7: inf | FE7: 09-27-2025-Sat 13-27-45-PM | FF7: 0.5 | FG7: 5.964 | FH7: -67.3176 | FI7: 14.91 | FJ7: 09-27-2025-Sat 13-27-45-PM | FK7: 0.1 | FL7: 5.968 | FM7: -64.337 | FN7: 74.6 | FO7: 09-27-2025-Sat 13-27-45-PM | FP7: -0.1 | FQ7: 5.968 | FR7: -65.6425 | FS7: -74.6 | FT7: 09-27-2025-Sat 13-27-45-PM | FU7: 0.3 | FV7: 5.964 | FW7: -63.483 | FX7: 24.85 | GI7: 09-27-2025-Sat 13-27-45-PM | GJ7: 0.2 | GK7: 5.972 | GL7: -62.026 | GM7: 37.325 | GN7: 09-27-2025-Sat 13-27-45-PM | GO7: 0.4 | GP7: 5.972 | GQ7: -61.763 | GR7: 18.6625 | GS7: 09-27-2025-Sat 13-27-45-PM | GT7: 0.4 | GU7: 5.96 | GV7: -63.685 | GW7: 18.625 | HM7: 08-29-2025-Fri 15-31-53-PM | HN7: 0.4 | HO7: 5.9 | HP7: -70.8937 | HQ7: 18.4375 | HR7: 08-29-2025-Fri 15-31-53-PM | HS7: 0.1 | HT7: 5.912 | HU7: -70.555 | HV7: 73.9 | HW7: 08-29-2025-Fri 15-31-53-PM | HX7: 0.5 | HY7: 5.912 | HZ7: -70.2379 | IA7: 14.78 | IB7: 08-29-2025-Fri 15-31-53-PM | IC7: 0.3 | ID7: 5.908 | IE7: -69.669 | IF7: 24.6167 | IG7: 08-29-2025-Fri 15-31-53-PM | IH7: 0 | II7: 5.9 | IJ7: -69.4508 | IK7: inf | IL7: 08-29-2025-Fri 15-31-53-PM | IM7: 0.2 | IN7: 5.916 | IO7: -69.702 | IP7: 36.975 | IV7: 08-29-2025-Fri 15-31-53-PM | IW7: 0.2 | IX7: 5.908 | IY7: -70.451 | IZ7: 36.925
A8: 10-24-2025-Fri 18-46-54-PM | B8: -0.1 | C8: 5.844 | D8: -54.8777 | E8: -73.05 | F8: 10-24-2025-Fri 18-46-54-PM | G8: -0.2 | H8: 5.86 | I8: -52.202 | J8: -36.625 | K8: 10-24-2025-Fri 18-46-54-PM | L8: 0.2 | M8: 5.848 | N8: -54.7128 | O8: 36.55 | P8: 10-24-2025-Fri 18-46-54-PM | Q8: 0.1 | R8: 5.852 | S8: -53.607 | T8: 73.15 | U8: 10-24-2025-Fri 18-46-54-PM | V8: 0 | W8: 5.856 | X8: -56.4275 | Y8: inf | Z8: 10-24-2025-Fri 18-46-54-PM | AA8: 0 | AB8: 5.856 | AC8: -52.895 | AD8: inf | AE8: 09-12-2025-Fri 12-24-54-PM | AF8: 0.2 | AG8: 5.944 | AH8: -50.6522 | AI8: 37.15 | AJ8: 09-12-2025-Fri 12-24-54-PM | AK8: 0.3 | AL8: 5.96 | AM8: -50.079 | AN8: 24.8333 | AO8: 09-12-2025-Fri 12-24-54-PM | AP8: -0.1 | AQ8: 5.948 | AR8: -50.5531 | AS8: -74.35 | AT8: 09-12-2025-Fri 12-24-54-PM | AU8: 0.2 | AV8: 5.952 | AW8: -50.404 | AX8: 37.2 | AY8: 09-12-2025-Fri 12-24-54-PM | AZ8: 0.4 | BA8: 5.948 | BB8: -52.9308 | BC8: 18.5875 | BD8: 09-12-2025-Fri 12-24-54-PM | BE8: 0.4 | BF8: 5.956 | BG8: -51.357 | BH8: 18.6125 | BI8: 09-12-2025-Fri 12-24-54-PM | BJ8: 0.2 | BK8: 5.956 | BL8: -51.3129 | BM8: 37.225 | BN8: 09-12-2025-Fri 12-24-54-PM | BO8: 0.1 | BP8: 5.956 | BQ8: -50.201 | BR8: 74.45 | BS8: 10-24-2025-Fri 18-46-54-PM | BT8: 0.3 | BU8: 5.848 | BV8: -58.4378 | BW8: 24.3667 | BX8: 10-24-2025-Fri 18-46-54-PM | BY8: 0.3 | BZ8: 5.86 | CA8: -54.985 | CB8: 24.4167 | CR8: 10-24-2025-Fri 18-46-54-PM | CS8: 0.4 | CT8: 5.856 | CU8: -52.5017 | CV8: 18.3 | CW8: 10-24-2025-Fri 18-46-54-PM | CX8: 0.6 | CY8: 5.852 | CZ8: -54.264 | DA8: 12.1917 | DQ8: 09-05-2025-Fri 20-15-25-PM | DR8: 0.5 | DS8: 5.904 | DT8: -66.1682 | DU8: 14.76 | DV8: 09-05-2025-Fri 20-15-25-PM | DW8: 0.1 | DX8: 5.908 | DY8: -64.547 | DZ8: 73.85 | EA8: 09-05-2025-Fri 20-15-25-PM | EB8: 0.6 | EC8: 5.912 | ED8: -64.6239 | EE8: 12.3167 | EF8: 09-05-2025-Fri 20-15-25-PM | EG8: 0.3 | EH8: 5.912 | EI8: -62.771 | EJ8: 24.6333 | EK8: 09-27-2025-Sat 13-27-48-PM | EL8: 0 | EM8: 5.956 | EN8: -65.1497 | EO8: inf | EP8: 09-27-2025-Sat 13-27-48-PM | EQ8: 0 | ER8: 5.972 | ES8: -63.166 | ET8: inf | EU8: 09-27-2025-Sat 13-27-48-PM | EV8: 0.1 | EW8: 5.96 | EX8: -63.8022 | EY8: 74.5 | EZ8: 09-27-2025-Sat 13-27-48-PM | FA8: 0.1 | FB8: 5.964 | FC8: -62.799 | FD8: 74.55 | FE8: 09-27-2025-Sat 13-27-48-PM | FF8: 0.3 | FG8: 5.964 | FH8: -67.3504 | FI8: 24.85 | FJ8: 09-27-2025-Sat 13-27-48-PM | FK8: 0.1 | FL8: 5.968 | FM8: -64.392 | FN8: 74.6 | FO8: 09-27-2025-Sat 13-27-48-PM | FP8: 0 | FQ8: 5.968 | FR8: -65.6754 | FS8: inf | FT8: 09-27-2025-Sat 13-27-48-PM | FU8: 0.4 | FV8: 5.968 | FW8: -63.538 | FX8: 18.65 | GI8: 09-27-2025-Sat 13-27-48-PM | GJ8: 0.3 | GK8: 5.968 | GL8: -62.048 | GM8: 24.8667 | GN8: 09-27-2025-Sat 13-27-48-PM | GO8: 0.2 | GP8: 5.972 | GQ8: -61.7959 | GR8: 37.325 | GS8: 09-27-2025-Sat 13-27-48-PM | GT8: 0.3 | GU8: 5.964 | GV8: -63.75 | GW8: 24.85 | HM8: 08-29-2025-Fri 15-31-56-PM | HN8: 0 | HO8: 5.904 | HP8: -70.8937 | HQ8: inf | HR8: 08-29-2025-Fri 15-31-56-PM | HS8: 0.4 | HT8: 5.912 | HU8: -70.555 | HV8: 18.475 | HW8: 08-29-2025-Fri 15-31-56-PM | HX8: 0 | HY8: 5.912 | HZ8: -70.2379 | IA8: inf | IB8: 08-29-2025-Fri 15-31-56-PM | IC8: 0.5 | ID8: 5.908 | IE8: -69.658 | IF8: 14.77 | IG8: 08-29-2025-Fri 15-31-56-PM | IH8: 0.5 | II8: 5.904 | IJ8: -69.4836 | IK8: 14.76 | IL8: 08-29-2025-Fri 15-31-56-PM | IM8: 0.1 | IN8: 5.916 | IO8: -69.702 | IP8: 73.95 | IQ8: 08-29-2025-Fri 15-31-56-PM | IR8: 0.1 | IS8: 5.904 | IT8: -71.0249 | IU8: 73.8 | IV8: 08-29-2025-Fri 15-31-56-PM | IW8: 0.4 | IX8: 5.908 | IY8: -70.435 | IZ8: 18.4625
A9: 10-24-2025-Fri 18-46-56-PM | B9: -0.2 | C9: 5.848 | D9: -54.9107 | E9: -36.55 | F9: 10-24-2025-Fri 18-46-56-PM | G9: 0.1 | H9: 5.864 | I9: -52.235 | J9: 73.3 | K9: 10-24-2025-Fri 18-46-56-PM | L9: -0.2 | M9: 5.848 | N9: -54.7128 | O9: -36.55 | P9: 10-24-2025-Fri 18-46-56-PM | Q9: 0.1 | R9: 5.852 | S9: -53.624 | T9: 73.15 | U9: 10-24-2025-Fri 18-46-56-PM | V9: 0.2 | W9: 5.856 | X9: -56.4606 | Y9: 36.6 | Z9: 10-24-2025-Fri 18-46-56-PM | AA9: 0 | AB9: 5.856 | AC9: -52.95 | AD9: inf | AE9: 09-12-2025-Fri 12-24-56-PM | AF9: 0.2 | AG9: 5.944 | AH9: -50.6853 | AI9: 37.15 | AJ9: 09-12-2025-Fri 12-24-56-PM | AK9: 0.2 | AL9: 5.96 | AM9: -50.09 | AN9: 37.25 | AO9: 09-12-2025-Fri 12-24-56-PM | AP9: 0.1 | AQ9: 5.948 | AR9: -50.5862 | AS9: 74.35 | AT9: 09-12-2025-Fri 12-24-56-PM | AU9: 0.2 | AV9: 5.952 | AW9: -50.438 | AX9: 37.2 | AY9: 09-12-2025-Fri 12-24-56-PM | AZ9: 0.3 | BA9: 5.952 | BB9: -52.9308 | BC9: 24.8 | BD9: 09-12-2025-Fri 12-24-56-PM | BE9: 0.4 | BF9: 5.96 | BG9: -51.368 | BH9: 18.625 | BI9: 09-12-2025-Fri 12-24-56-PM | BJ9: 0.2 | BK9: 5.956 | BL9: -51.3459 | BM9: 37.225 | BN9: 09-12-2025-Fri 12-24-56-PM | BO9: 0.1 | BP9: 5.956 | BQ9: -50.2 | BR9: 74.45 | BS9: 10-24-2025-Fri 18-46-56-PM | BT9: 0.2 | BU9: 5.848 | BV9: -58.4708 | BW9: 36.55 | BX9: 10-24-2025-Fri 18-46-56-PM | BY9: 0.4 | BZ9: 5.856 | CA9: -55.029 | CB9: 18.3 | CR9: 10-24-2025-Fri 18-46-56-PM | CS9: 0.3 | CT9: 5.86 | CU9: -52.5347 | CV9: 24.4167 | CW9: 10-24-2025-Fri 18-46-56-PM | CX9: 0.4 | CY9: 5.852 | CZ9: -54.314 | DA9: 18.2875 | DB9: 10-24-2025-Fri 18-46-56-PM | DC9: 0.1 | DD9: 5.856 | DE9: -50.1567 | DF9: 73.2 | DQ9: 09-05-2025-Fri 20-15-27-PM | DR9: 0.3 | DS9: 5.908 | DT9: -66.201 | DU9: 24.6167 | DV9: 09-05-2025-Fri 20-15-27-PM | DW9: 0.1 | DX9: 5.912 | DY9: -64.558 | DZ9: 73.9 | EA9: 09-05-2025-Fri 20-15-27-PM | EB9: 0.3 | EC9: 5.908 | ED9: -64.6567 | EE9: 24.6167 | EF9: 09-05-2025-Fri 20-15-27-PM | EG9: 0.4 | EH9: 5.908 | EI9: -62.793 | EJ9: 18.4625 | EK9: 09-27-2025-Sat 13-27-50-PM | EL9: 0.2 | EM9: 5.96 | EN9: -65.1497 | EO9: 37.25 | EP9: 09-27-2025-Sat 13-27-50-PM | EQ9: 0.2 | ER9: 5.976 | ES9: -63.188 | ET9: 37.35 | EU9: 09-27-2025-Sat 13-27-50-PM | EV9: 0.1 | EW9: 5.96 | EX9: -63.835 | EY9: 74.5 | EZ9: 09-27-2025-Sat 13-27-50-PM | FA9: 0.1 | FB9: 5.964 | FC9: -62.832 | FD9: 74.55 | FE9: 09-27-2025-Sat 13-27-50-PM | FF9: 0.3 | FG9: 5.96 | FH9: -67.3504 | FI9: 24.8333 | FJ9: 09-27-2025-Sat 13-27-50-PM | FK9: 0.2 | FL9: 5.968 | FM9: -64.381 | FN9: 37.3 | FO9: 09-27-2025-Sat 13-27-50-PM | FP9: 0.3 | FQ9: 5.972 | FR9: -65.7083 | FS9: 24.8833 | FT9: 09-27-2025-Sat 13-27-50-PM | FU9: 0.2 | FV9: 5.964 | FW9: -63.549 | FX9: 37.275 | GD9: 09-27-2025-Sat 13-27-50-PM | GE9: 0 | GF9: 5.972 | GG9: -60.5783 | GH9: inf | GI9: 09-27-2025-Sat 13-27-50-PM | GJ9: 0.1 | GK9: 5.972 | GL9: -62.081 | GM9: 74.65 | GN9: 09-27-2025-Sat 13-27-50-PM | GO9: 0.4 | GP9: 5.968 | GQ9: -61.8288 | GR9: 18.65 | GS9: 09-27-2025-Sat 13-27-50-PM | GT9: 0.4 | GU9: 5.96 | GV9: -63.717 | GW9: 18.625 | HM9: 08-29-2025-Fri 15-31-58-PM | HN9: 0.2 | HO9: 5.904 | HP9: -70.9266 | HQ9: 36.9 | HR9: 08-29-2025-Fri 15-31-58-PM | HS9: 0.1 | HT9: 5.912 | HU9: -70.566 | HV9: 73.9 | HW9: 08-29-2025-Fri 15-31-58-PM | HX9: 0.3 | HY9: 5.908 | HZ9: -70.2379 | IA9: 24.6167 | IB9: 08-29-2025-Fri 15-31-58-PM | IC9: 0.4 | ID9: 5.908 | IE9: -69.691 | IF9: 18.4625 | IG9: 08-29-2025-Fri 15-31-58-PM | IH9: 0 | II9: 5.9 | IJ9: -69.5164 | IK9: inf | IL9: 08-29-2025-Fri 15-31-58-PM | IM9: 0.4 | IN9: 5.916 | IO9: -69.713 | IP9: 18.4875 | IQ9: 08-29-2025-Fri 15-31-58-PM | IR9: 0.2 | IS9: 5.904 | IT9: -71.0249 | IU9: 36.9 | IV9: 08-29-2025-Fri 15-31-58-PM | IW9: 0.3 | IX9: 5.904 | IY9: -70.451 | IZ9: 24.6
A10: 10-24-2025-Fri 18-46-59-PM | B10: -0.1 | C10: 5.848 | D10: -54.9436 | E10: -73.1 | F10: 10-24-2025-Fri 18-46-59-PM | G10: 0 | H10: 5.864 | I10: -52.268 | J10: inf | K10: 10-24-2025-Fri 18-46-59-PM | L10: 0.1 | M10: 5.852 | N10: -54.7457 | O10: 73.15 | P10: 10-24-2025-Fri 18-46-59-PM | Q10: 0.1 | R10: 5.852 | S10: -53.657 | T10: 73.15 | U10: 10-24-2025-Fri 18-46-59-PM | V10: -0.1 | W10: 5.856 | X10: -56.4606 | Y10: -73.2 | Z10: 10-24-2025-Fri 18-46-59-PM | AA10: 0.2 | AB10: 5.856 | AC10: -52.939 | AD10: 36.6 | AE10: 09-12-2025-Fri 12-24-59-PM | AF10: -0.1 | AG10: 5.948 | AH10: -50.6853 | AI10: -74.35 | AJ10: 09-12-2025-Fri 12-24-59-PM | AK10: 0.1 | AL10: 5.964 | AM10: -50.113 | AN10: 74.55 | AO10: 09-12-2025-Fri 12-24-59-PM | AP10: 0.2 | AQ10: 5.948 | AR10: -50.5862 | AS10: 37.175 | AT10: 09-12-2025-Fri 12-24-59-PM | AU10: 0.1 | AV10: 5.952 | AW10: -50.454 | AX10: 74.4 | AY10: 09-12-2025-Fri 12-24-59-PM | AZ10: 0.4 | BA10: 5.948 | BB10: -52.9308 | BC10: 18.5875 | BD10: 09-12-2025-Fri 12-24-59-PM | BE10: 0.3 | BF10: 5.956 | BG10: -51.401 | BH10: 24.8167 | BI10: 09-12-2025-Fri 12-24-59-PM | BJ10: 0.3 | BK10: 5.96 | BL10: -51.3129 | BM10: 24.8333 | BN10: 09-12-2025-Fri 12-24-59-PM | BO10: 0.3 | BP10: 5.956 | BQ10: -50.223 | BR10: 24.8167 | BS10: 10-24-2025-Fri 18-46-59-PM | BT10: 0.4 | BU10: 5.848 | BV10: -58.5037 | BW10: 18.275 | BX10: 10-24-2025-Fri 18-46-59-PM | BY10: 0.1 | BZ10: 5.856 | CA10: -55.073 | CB10: 73.2 | CR10: 10-24-2025-Fri 18-46-59-PM | CS10: 0.4 | CT10: 5.856 | CU10: -52.5678 | CV10: 18.3 | CW10: 10-24-2025-Fri 18-46-59-PM | CX10: 0.5 | CY10: 5.852 | CZ10: -54.38 | DA10: 14.63 | DB10: 10-24-2025-Fri 18-46-59-PM | DC10: 0.6 | DD10: 5.856 | DE10: -50.2558 | DF10: 12.2 | DQ10: 09-05-2025-Fri 20-16-10-PM | DR10: 0.1 | DS10: 5.9 | DT10: -66.5623 | DU10: 73.75 | DV10: 09-05-2025-Fri 20-16-10-PM | DW10: 0.2 | DX10: 5.912 | DY10: -64.941 | DZ10: 36.95 | EA10: 09-05-2025-Fri 20-16-10-PM | EB10: 0.1 | EC10: 5.912 | ED10: -65.0183 | EE10: 73.9 | EF10: 09-05-2025-Fri 20-16-10-PM | EG10: 0.3 | EH10: 5.908 | EI10: -63.188 | EJ10: 24.6167 | EK10: 09-27-2025-Sat 13-27-52-PM | EL10: 0.2 | EM10: 5.96 | EN10: -65.1826 | EO10: 37.25 | EP10: 09-27-2025-Sat 13-27-52-PM | EQ10: 0.2 | ER10: 5.972 | ES10: -63.21 | ET10: 37.325 | EU10: 09-27-2025-Sat 13-27-52-PM | EV10: 0.3 | EW10: 5.96 | EX10: -63.8679 | EY10: 24.8333 | EZ10: 09-27-2025-Sat 13-27-52-PM | FA10: 0.3 | FB10: 5.968 | FC10: -62.865 | FD10: 24.8667 | FE10: 09-27-2025-Sat 13-27-52-PM | FF10: 0.3 | FG10: 5.956 | FH10: -67.3832 | FI10: 24.8167 | FJ10: 09-27-2025-Sat 13-27-52-PM | FK10: 0.3 | FL10: 5.972 | FM10: -64.436 | FN10: 24.8833 | FO10: 09-27-2025-Sat 13-27-52-PM | FP10: 0 | FQ10: 5.972 | FR10: -65.7083 | FS10: inf | FT10: 09-27-2025-Sat 13-27-52-PM | FU10: 0.4 | FV10: 5.964 | FW10: -63.593 | FX10: 18.6375 | GD10: 09-27-2025-Sat 13-27-52-PM | GE10: 0.6 | GF10: 5.972 | GG10: -60.5783 | GH10: 12.4417 | GI10: 09-27-2025-Sat 13-27-52-PM | GJ10: 0.2 | GK10: 5.968 | GL10: -62.103 | GM10: 37.3 | GN10: 09-27-2025-Sat 13-27-52-PM | GO10: 0.2 | GP10: 5.968 | GQ10: -61.8617 | GR10: 37.3 | GS10: 09-27-2025-Sat 13-27-52-PM | GT10: 0.2 | GU10: 5.96 | GV10: -63.8 | GW10: 37.25 | HM10: 08-29-2025-Fri 15-32-00-PM | HN10: 0.1 | HO10: 5.904 | HP10: -70.9266 | HQ10: 73.8 | HR10: 08-29-2025-Fri 15-32-00-PM | HS10: 0.1 | HT10: 5.912 | HU10: -70.588 | HV10: 73.9 | HW10: 08-29-2025-Fri 15-32-00-PM | HX10: 0.1 | HY10: 5.912 | HZ10: -70.2708 | IA10: 73.9 | IB10: 08-29-2025-Fri 15-32-00-PM | IC10: 0.1 | ID10: 5.912 | IE10: -69.713 | IF10: 73.9 | IG10: 08-29-2025-Fri 15-32-00-PM | IH10: 0.2 | II10: 5.904 | IJ10: -69.5164 | IK10: 36.9 | IL10: 08-29-2025-Fri 15-32-00-PM | IM10: 0.3 | IN10: 5.916 | IO10: -69.757 | IP10: 24.65 | IQ10: 08-29-2025-Fri 15-32-00-PM | IR10: 0.5 | IS10: 5.904 | IT10: -71.1561 | IU10: 14.76 | IV10: 08-29-2025-Fri 15-32-00-PM | IW10: 0.2 | IX10: 5.904 | IY10: -70.517 | IZ10: 36.9
A11: 10-24-2025-Fri 18-48-56-PM | B11: -0.1 | C11: 5.848 | D11: -56.1309 | E11: -73.1 | F11: 10-24-2025-Fri 18-48-56-PM | G11: 0 | H11: 5.86 | I11: -53.809 | J11: inf | K11: 10-24-2025-Fri 18-48-56-PM | L11: 0 | M11: 5.848 | N11: -55.9989 | O11: inf | P11: 10-24-2025-Fri 18-48-56-PM | Q11: 0 | R11: 5.852 | S11: -55.141 | T11: inf | U11: 10-24-2025-Fri 18-48-56-PM | V11: 0.1 | W11: 5.856 | X11: -57.3175 | Y11: 73.2 | Z11: 10-24-2025-Fri 18-48-56-PM | AA11: 0.1 | AB11: 5.856 | AC11: -54.348 | AD11: 73.2 | AE11: 09-12-2025-Fri 12-25-01-PM | AF11: 0 | AG11: 5.944 | AH11: -50.7184 | AI11: inf | AJ11: 09-12-2025-Fri 12-25-01-PM | AK11: 0.1 | AL11: 5.964 | AM11: -50.135 | AN11: 74.55 | AO11: 09-12-2025-Fri 12-25-01-PM | AP11: 0.2 | AQ11: 5.948 | AR11: -50.6192 | AS11: 37.175 | AT11: 09-12-2025-Fri 12-25-01-PM | AU11: 0.2 | AV11: 5.952 | AW11: -50.47 | AX11: 37.2 | AY11: 09-12-2025-Fri 12-25-01-PM | AZ11: 0.4 | BA11: 5.948 | BB11: -52.9308 | BC11: 18.5875 | BD11: 09-12-2025-Fri 12-25-01-PM | BE11: 0.1 | BF11: 5.956 | BG11: -51.379 | BH11: 74.45 | BI11: 09-12-2025-Fri 12-25-01-PM | BJ11: 0.1 | BK11: 5.956 | BL11: -51.379 | BM11: 74.45 | BN11: 09-12-2025-Fri 12-25-01-PM | BO11: 0.4 | BP11: 5.956 | BQ11: -50.234 | BR11: 18.6125 | BS11: 10-24-2025-Fri 18-48-56-PM | BT11: 0.6 | BU11: 5.848 | BV11: -58.9978 | BW11: 12.1833 | BX11: 10-24-2025-Fri 18-48-56-PM | BY11: 0.4 | BZ11: 5.856 | CA11: -56.184 | CB11: 18.3 | CM11: 10-24-2025-Fri 18-48-56-PM | CN11: -0.1 | CO11: 5.856 | CP11: -53.193 | CQ11: -73.2 | CR11: 10-24-2025-Fri 18-48-56-PM | CS11: 0.4 | CT11: 5.86 | CU11: -54.2838 | CV11: 18.3125 | CW11: 10-24-2025-Fri 18-48-56-PM | CX11: 0.3 | CY11: 5.852 | CZ11: -55.618 | DA11: 24.3833 | DB11: 10-24-2025-Fri 18-48-56-PM | DC11: 0.5 | DD11: 5.856 | DE11: -52.2375 | DF11: 14.64 | DQ11: 09-05-2025-Fri 20-16-12-PM | DR11: 0.2 | DS11: 5.904 | DT11: -66.5952 | DU11: 36.9 | DV11: 09-05-2025-Fri 20-16-12-PM | DW11: 0.3 | DX11: 5.908 | DY11: -64.974 | DZ11: 24.6167 | EA11: 09-05-2025-Fri 20-16-12-PM | EB11: 0.2 | EC11: 5.912 | ED11: -65.0511 | EE11: 36.95 | EF11: 09-05-2025-Fri 20-16-12-PM | EG11: 0.3 | EH11: 5.908 | EI11: -63.221 | EJ11: 24.6167 | EK11: 09-27-2025-Sat 13-28-35-PM | EL11: 0.1 | EM11: 5.96 | EN11: -65.6098 | EO11: 74.5 | EP11: 09-27-2025-Sat 13-28-35-PM | EQ11: 0.2 | ER11: 5.976 | ES11: -63.703 | ET11: 37.35 | EU11: 09-27-2025-Sat 13-28-35-PM | EV11: 0.1 | EW11: 5.96 | EX11: -64.328 | EY11: 74.5 | EZ11: 09-27-2025-Sat 13-28-35-PM | FA11: 0.1 | FB11: 5.968 | FC11: -63.391 | FD11: 74.6 | FE11: 09-27-2025-Sat 13-28-35-PM | FF11: 0.4 | FG11: 5.964 | FH11: -67.6787 | FI11: 18.6375 | FJ11: 09-27-2025-Sat 13-28-35-PM | FK11: -0.2 | FL11: 5.968 | FM11: -64.852 | FN11: -37.3 | FO11: 09-27-2025-Sat 13-28-35-PM | FP11: -0.1 | FQ11: 5.972 | FR11: -66.1025 | FS11: -74.65 | FT11: 09-27-2025-Sat 13-28-35-PM | FU11: 0.2 | FV11: 5.968 | FW11: -64.031 | FX11: 37.3 | GD11: 09-27-2025-Sat 13-28-35-PM | GE11: 0.7 | GF11: 5.972 | GG11: -61.1707 | GH11: 10.6643 | GI11: 09-27-2025-Sat 13-28-35-PM | GJ11: 0 | GK11: 5.972 | GL11: -62.651 | GM11: inf | GN11: 09-27-2025-Sat 13-28-35-PM | GO11: 0.1 | GP11: 5.972 | GQ11: -62.4539 | GR11: 74.65 | GS11: 09-27-2025-Sat 13-28-35-PM | GT11: 0.1 | GU11: 5.968 | GV11: -64.227 | GW11: 74.6 | HM11: 08-29-2025-Fri 15-32-03-PM | HN11: 0.4 | HO11: 5.904 | HP11: -70.9266 | HQ11: 18.45 | HR11: 08-29-2025-Fri 15-32-03-PM | HS11: 0.2 | HT11: 5.912 | HU11: -70.588 | HV11: 36.95 | HW11: 08-29-2025-Fri 15-32-03-PM | HX11: 0.2 | HY11: 5.908 | HZ11: -70.3036 | IA11: 36.925 | IB11: 08-29-2025-Fri 15-32-03-PM | IC11: 0.1 | ID11: 5.908 | IE11: -69.735 | IF11: 73.85 | IG11: 08-29-2025-Fri 15-32-03-PM | IH11: 0 | II11: 5.904 | IJ11: -69.5164 | IK11: inf | IL11: 08-29-2025-Fri 15-32-03-PM | IM11: 0.6 | IN11: 5.916 | IO11: -69.746 | IP11: 12.325 | IQ11: 08-29-2025-Fri 15-32-03-PM | IR11: 0.4 | IS11: 5.904 | IT11: -71.0905 | IU11: 18.45 | IV11: 08-29-2025-Fri 15-32-03-PM | IW11: 0.4 | IX11: 5.908 | IY11: -70.5 | IZ11: 18.4625
A12: 10-24-2025-Fri 18-48-58-PM | B12: 0.2 | C12: 5.852 | D12: -56.1309 | E12: 36.575 | F12: 10-24-2025-Fri 18-48-58-PM | G12: 0.1 | H12: 5.86 | I12: -53.842 | J12: 73.25 | K12: 10-24-2025-Fri 18-48-58-PM | L12: 0.2 | M12: 5.852 | N12: -56.0649 | O12: 36.575 | P12: 10-24-2025-Fri 18-48-58-PM | Q12: 0.1 | R12: 5.852 | S12: -55.191 | T12: 73.15 | U12: 10-24-2025-Fri 18-48-58-PM | V12: -0.2 | W12: 5.86 | X12: -57.3505 | Y12: -36.625 | Z12: 10-24-2025-Fri 18-48-58-PM | AA12: 0.3 | AB12: 5.856 | AC12: -54.37 | AD12: 24.4 | AE12: 09-12-2025-Fri 12-25-03-PM | AF12: 0 | AG12: 5.944 | AH12: -50.7184 | AI12: inf | AJ12: 09-12-2025-Fri 12-25-03-PM | AK12: 0.1 | AL12: 5.96 | AM12: -50.135 | AN12: 74.5 | AO12: 09-12-2025-Fri 12-25-03-PM | AP12: 0.3 | AQ12: 5.948 | AR12: -50.6192 | AS12: 24.7833 | AT12: 09-12-2025-Fri 12-25-03-PM | AU12: 0.3 | AV12: 5.956 | AW12: -50.47 | AX12: 24.8167 | AY12: 09-12-2025-Fri 12-25-03-PM | AZ12: 0.5 | BA12: 5.948 | BB12: -52.9638 | BC12: 14.87 | BD12: 09-12-2025-Fri 12-25-03-PM | BE12: 0.2 | BF12: 5.956 | BG12: -51.423 | BH12: 37.225 | BI12: 09-12-2025-Fri 12-25-03-PM | BJ12: -0.1 | BK12: 5.956 | BL12: -51.379 | BM12: -74.45 | BN12: 09-12-2025-Fri 12-25-03-PM | BO12: 0.1 | BP12: 5.956 | BQ12: -50.245 | BR12: 74.45 | BS12: 10-24-2025-Fri 18-48-58-PM | BT12: 0.2 | BU12: 5.852 | BV12: -58.9648 | BW12: 36.575 | BX12: 10-24-2025-Fri 18-48-58-PM | BY12: 0.3 | BZ12: 5.86 | CA12: -56.217 | CB12: 24.4167 | CM12: 10-24-2025-Fri 18-48-58-PM | CN12: 0.2 | CO12: 5.86 | CP12: -53.237 | CQ12: 36.625 | CR12: 10-24-2025-Fri 18-48-58-PM | CS12: 0.4 | CT12: 5.86 | CU12: -54.3168 | CV12: 18.3125 | CW12: 10-24-2025-Fri 18-48-58-PM | CX12: 0.6 | CY12: 5.848 | CZ12: -55.651 | DA12: 12.1833 | DB12: 10-24-2025-Fri 18-48-58-PM | DC12: 0.4 | DD12: 5.856 | DE12: -52.3366 | DF12: 18.3 | DQ12: 09-05-2025-Fri 20-16-15-PM | DR12: 0.1 | DS12: 5.904 | DT12: -66.6279 | DU12: 73.8 | DV12: 09-05-2025-Fri 20-16-15-PM | DW12: 0.2 | DX12: 5.908 | DY12: -64.985 | DZ12: 36.925 | EA12: 09-05-2025-Fri 20-16-15-PM | EB12: 0 | EC12: 5.908 | ED12: -65.084 | EE12: inf | EF12: 09-05-2025-Fri 20-16-15-PM | EG12: 0.1 | EH12: 5.912 | EI12: -63.243 | EJ12: 73.9 | EK12: 09-27-2025-Sat 13-28-37-PM | EL12: 0.3 | EM12: 5.96 | EN12: -65.6425 | EO12: 24.8333 | EP12: 09-27-2025-Sat 13-28-37-PM | EQ12: 0.2 | ER12: 5.972 | ES12: -63.736 | ET12: 37.325 | EU12: 09-27-2025-Sat 13-28-37-PM | EV12: -0.1 | EW12: 5.964 | EX12: -64.361 | EY12: -74.55 | EZ12: 09-27-2025-Sat 13-28-37-PM | FA12: 0 | FB12: 5.968 | FC12: -63.424 | FD12: inf | FE12: 09-27-2025-Sat 13-28-37-PM | FF12: 0.2 | FG12: 5.96 | FH12: -67.7115 | FI12: 37.25 | FJ12: 09-27-2025-Sat 13-28-37-PM | FK12: 0.2 | FL12: 5.968 | FM12: -64.896 | FN12: 37.3 | FO12: 09-27-2025-Sat 13-28-37-PM | FP12: 0.2 | FQ12: 5.968 | FR12: -66.1353 | FS12: 37.3 | FT12: 09-27-2025-Sat 13-28-37-PM | FU12: 0.2 | FV12: 5.968 | FW12: -64.075 | FX12: 37.3 | GD12: 09-27-2025-Sat 13-28-37-PM | GE12: 0.3 | GF12: 5.972 | GG12: -61.2036 | GH12: 24.8833 | GI12: 09-27-2025-Sat 13-28-37-PM | GJ12: 0 | GK12: 5.972 | GL12: -62.684 | GM12: inf | GN12: 09-27-2025-Sat 13-28-37-PM | GO12: 0.3 | GP12: 5.972 | GQ12: -62.4868 | GR12: 24.8833 | GS12: 09-27-2025-Sat 13-28-37-PM | GT12: 0.5 | GU12: 5.964 | GV12: -64.277 | GW12: 14.91 | HM12: 08-29-2025-Fri 15-32-05-PM | HN12: 0.2 | HO12: 5.904 | HP12: -70.9594 | HQ12: 36.9 | HR12: 08-29-2025-Fri 15-32-05-PM | HS12: 0.4 | HT12: 5.908 | HU12: -70.61 | HV12: 18.4625 | HW12: 08-29-2025-Fri 15-32-05-PM | HX12: 0.1 | HY12: 5.912 | HZ12: -70.3364 | IA12: 73.9 | IB12: 08-29-2025-Fri 15-32-05-PM | IC12: 0.3 | ID12: 5.912 | IE12: -69.768 | IF12: 24.6333 | IG12: 08-29-2025-Fri 15-32-05-PM | IH12: 0.4 | II12: 5.9 | IJ12: -69.5492 | IK12: 18.4375 | IL12: 08-29-2025-Fri 15-32-05-PM | IM12: 0.1 | IN12: 5.916 | IO12: -69.768 | IP12: 73.95 | IQ12: 08-29-2025-Fri 15-32-05-PM | IR12: 0.2 | IS12: 5.904 | IT12: -71.0905 | IU12: 36.9 | IV12: 08-29-2025-Fri 15-32-05-PM | IW12: 0.3 | IX12: 5.908 | IY12: -70.5 | IZ12: 24.6167
A13: 10-24-2025-Fri 18-49-00-PM | B13: 0.1 | C13: 5.848 | D13: -56.1309 | E13: 73.1 | F13: 10-24-2025-Fri 18-49-00-PM | G13: 0.2 | H13: 5.864 | I13: -53.853 | J13: 36.65 | K13: 10-24-2025-Fri 18-49-00-PM | L13: 0.1 | M13: 5.848 | N13: -56.0649 | O13: 73.1 | P13: 10-24-2025-Fri 18-49-00-PM | Q13: 0.2 | R13: 5.852 | S13: -55.207 | T13: 36.575 | U13: 10-24-2025-Fri 18-49-00-PM | V13: 0 | W13: 5.86 | X13: -57.3835 | Y13: inf | Z13: 10-24-2025-Fri 18-49-00-PM | AA13: 0.2 | AB13: 5.856 | AC13: -54.381 | AD13: 36.6 | AE13: 09-12-2025-Fri 12-25-06-PM | AF13: 0.2 | AG13: 5.948 | AH13: -50.7184 | AI13: 37.175 | AJ13: 09-12-2025-Fri 12-25-06-PM | AK13: 0.2 | AL13: 5.964 | AM13: -50.146 | AN13: 37.275 | AO13: 09-12-2025-Fri 12-25-06-PM | AP13: 0.2 | AQ13: 5.948 | AR13: -50.6192 | AS13: 37.175 | AT13: 09-12-2025-Fri 12-25-06-PM | AU13: 0.2 | AV13: 5.952 | AW13: -50.47 | AX13: 37.2 | AY13: 09-12-2025-Fri 12-25-06-PM | AZ13: 0.5 | BA13: 5.948 | BB13: -52.9638 | BC13: 14.87 | BD13: 09-12-2025-Fri 12-25-06-PM | BE13: 0.4 | BF13: 5.956 | BG13: -51.423 | BH13: 18.6125 | BI13: 09-12-2025-Fri 12-25-06-PM | BJ13: 0.5 | BK13: 5.956 | BL13: -51.379 | BM13: 14.89 | BN13: 09-12-2025-Fri 12-25-06-PM | BO13: 0.1 | BP13: 5.956 | BQ13: -50.245 | BR13: 74.45 | BS13: 10-24-2025-Fri 18-49-00-PM | BT13: 0.1 | BU13: 5.852 | BV13: -58.9978 | BW13: 73.15 | BX13: 10-24-2025-Fri 18-49-00-PM | BY13: 0.2 | BZ13: 5.856 | CA13: -56.217 | CB13: 36.6 | CM13: 10-24-2025-Fri 18-49-00-PM | CN13: 0.2 | CO13: 5.856 | CP13: -53.259 | CQ13: 36.6 | CR13: 10-24-2025-Fri 18-49-00-PM | CS13: 0.6 | CT13: 5.856 | CU13: -54.3499 | CV13: 12.2 | CW13: 10-24-2025-Fri 18-49-00-PM | CX13: 0.3 | CY13: 5.852 | CZ13: -55.634 | DA13: 24.3833 | DB13: 10-24-2025-Fri 18-49-00-PM | DC13: 0.7 | DD13: 5.856 | DE13: -52.2706 | DF13: 10.4571 | DL13: 10-24-2025-Fri 18-49-00-PM | DM13: 0.1 | DN13: 5.86 | DO13: -49.628 | DP13: 73.25 | DQ13: 09-05-2025-Fri 20-16-17-PM | DR13: 0.3 | DS13: 5.9 | DT13: -66.6279 | DU13: 24.5833 | DV13: 09-05-2025-Fri 20-16-17-PM | DW13: 0.1 | DX13: 5.908 | DY13: -65.007 | DZ13: 73.85 | EA13: 09-05-2025-Fri 20-16-17-PM | EB13: 0.1 | EC13: 5.912 | ED13: -65.1169 | EE13: 73.9 | EF13: 09-05-2025-Fri 20-16-17-PM | EG13: 0.5 | EH13: 5.908 | EI13: -63.265 | EJ13: 14.77 | EK13: 09-27-2025-Sat 13-28-40-PM | EL13: 0.2 | EM13: 5.96 | EN13: -65.6425 | EO13: 37.25 | EP13: 09-27-2025-Sat 13-28-40-PM | EQ13: 0.3 | ER13: 5.976 | ES13: -63.758 | ET13: 24.9 | EU13: 09-27-2025-Sat 13-28-40-PM | EV13: 0.2 | EW13: 5.964 | EX13: -64.4267 | EY13: 37.275 | EZ13: 09-27-2025-Sat 13-28-40-PM | FA13: 0.2 | FB13: 5.964 | FC13: -63.457 | FD13: 37.275 | FE13: 09-27-2025-Sat 13-28-40-PM | FF13: 0.4 | FG13: 5.964 | FH13: -67.7115 | FI13: 18.6375 | FJ13: 09-27-2025-Sat 13-28-40-PM | FK13: -0.1 | FL13: 5.968 | FM13: -64.885 | FN13: -74.6 | FO13: 09-27-2025-Sat 13-28-40-PM | FP13: 0 | FQ13: 5.972 | FR13: -66.1353 | FS13: inf | FT13: 09-27-2025-Sat 13-28-40-PM | FU13: 0.4 | FV13: 5.968 | FW13: -64.064 | FX13: 18.65 | GD13: 09-27-2025-Sat 13-28-40-PM | GE13: 0.4 | GF13: 5.972 | GG13: -61.2036 | GH13: 18.6625 | GI13: 09-27-2025-Sat 13-28-40-PM | GJ13: 0.4 | GK13: 5.972 | GL13: -62.706 | GM13: 18.6625 | GN13: 09-27-2025-Sat 13-28-40-PM | GO13: 0.5 | GP13: 5.976 | GQ13: -62.4868 | GR13: 14.94 | GS13: 09-27-2025-Sat 13-28-40-PM | GT13: 0.2 | GU13: 5.964 | GV13: -64.26 | GW13: 37.275 | HM13: 08-29-2025-Fri 15-33-45-PM | HN13: 0.4 | HO13: 5.904 | HP13: -71.9755 | HQ13: 18.45 | HR13: 08-29-2025-Fri 15-33-45-PM | HS13: 0.3 | HT13: 5.912 | HU13: -71.67 | HV13: 24.6333 | HW13: 08-29-2025-Fri 15-33-45-PM | HX13: -0.1 | HY13: 5.912 | HZ13: -71.4511 | IA13: -73.9 | IB13: 08-29-2025-Fri 15-33-45-PM | IC13: 0.1 | ID13: 5.908 | IE13: -70.905 | IF13: 73.85 | IG13: 08-29-2025-Fri 15-33-45-PM | IH13: 0.2 | II13: 5.9 | IJ13: -70.5987 | IK13: 36.875 | IL13: 08-29-2025-Fri 15-33-45-PM | IM13: 0.3 | IN13: 5.916 | IO13: -70.883 | IP13: 24.65 | IQ13: 08-29-2025-Fri 15-33-45-PM | IR13: 0.3 | IS13: 5.904 | IT13: -72.1721 | IU13: 24.6 | IV13: 08-29-2025-Fri 15-33-45-PM | IW13: 0.3 | IX13: 5.908 | IY13: -71.664 | IZ13: 24.6167
A14: 10-24-2025-Fri 18-49-03-PM | B14: -0.2 | C14: 5.848 | D14: -56.1638 | E14: -36.55 | F14: 10-24-2025-Fri 18-49-03-PM | G14: -0.1 | H14: 5.86 | I14: -53.886 | J14: -73.25 | K14: 10-24-2025-Fri 18-49-03-PM | L14: 0 | M14: 5.848 | N14: -56.0978 | O14: inf | P14: 10-24-2025-Fri 18-49-03-PM | Q14: 0.3 | R14: 5.856 | S14: -55.224 | T14: 24.4 | U14: 10-24-2025-Fri 18-49-03-PM | V14: 0 | W14: 5.86 | X14: -57.3835 | Y14: inf | Z14: 10-24-2025-Fri 18-49-03-PM | AA14: 0.1 | AB14: 5.856 | AC14: -54.414 | AD14: 73.2 | AE14: 09-12-2025-Fri 12-25-08-PM | AF14: 0.1 | AG14: 5.948 | AH14: -50.7514 | AI14: 74.35 | AJ14: 09-12-2025-Fri 12-25-08-PM | AK14: 0.2 | AL14: 5.96 | AM14: -50.168 | AN14: 37.25 | AO14: 09-12-2025-Fri 12-25-08-PM | AP14: 0.2 | AQ14: 5.948 | AR14: -50.6522 | AS14: 37.175 | AT14: 09-12-2025-Fri 12-25-08-PM | AU14: 0.1 | AV14: 5.952 | AW14: -50.504 | AX14: 74.4 | AY14: 09-12-2025-Fri 12-25-08-PM | AZ14: 0.2 | BA14: 5.948 | BB14: -52.9638 | BC14: 37.175 | BD14: 09-12-2025-Fri 12-25-08-PM | BE14: 0.4 | BF14: 5.956 | BG14: -51.423 | BH14: 18.6125 | BI14: 09-12-2025-Fri 12-25-08-PM | BJ14: 0.2 | BK14: 5.96 | BL14: -51.412 | BM14: 37.25 | BN14: 09-12-2025-Fri 12-25-08-PM | BO14: 0.2 | BP14: 5.956 | BQ14: -50.267 | BR14: 37.225 | BS14: 10-24-2025-Fri 18-49-03-PM | BT14: 0.3 | BU14: 5.848 | BV14: -58.9978 | BW14: 24.3667 | BX14: 10-24-2025-Fri 18-49-03-PM | BY14: 0.3 | BZ14: 5.856 | CA14: -56.25 | CB14: 24.4 | CM14: 10-24-2025-Fri 18-49-03-PM | CN14: 0.3 | CO14: 5.86 | CP14: -53.281 | CQ14: 24.4167 | CR14: 10-24-2025-Fri 18-49-03-PM | CS14: 0.3 | CT14: 5.856 | CU14: -54.3499 | CV14: 24.4 | CW14: 10-24-2025-Fri 18-49-03-PM | CX14: 0.4 | CY14: 5.852 | CZ14: -55.684 | DA14: 18.2875 | DB14: 10-24-2025-Fri 18-49-03-PM | DC14: 0.3 | DD14: 5.856 | DE14: -52.3696 | DF14: 24.4 | DL14: 10-24-2025-Fri 18-49-03-PM | DM14: 0.5 | DN14: 5.86 | DO14: -49.6941 | DP14: 14.65 | DQ14: 09-05-2025-Fri 20-16-19-PM | DR14: 0.1 | DS14: 5.904 | DT14: -66.6279 | DU14: 73.8 | DV14: 09-05-2025-Fri 20-16-19-PM | DW14: 0 | DX14: 5.912 | DY14: -65.007 | DZ14: inf | EA14: 09-05-2025-Fri 20-16-19-PM | EB14: 0.1 | EC14: 5.912 | ED14: -65.1169 | EE14: 73.9 | EF14: 09-05-2025-Fri 20-16-19-PM | EG14: 0.3 | EH14: 5.912 | EI14: -63.298 | EJ14: 24.6333 | EK14: 09-27-2025-Sat 13-28-42-PM | EL14: -0.1 | EM14: 5.96 | EN14: -65.6425 | EO14: -74.5 | EP14: 09-27-2025-Sat 13-28-42-PM | EQ14: 0.1 | ER14: 5.972 | ES14: -63.769 | ET14: 74.65 | EU14: 09-27-2025-Sat 13-28-42-PM | EV14: 0.1 | EW14: 5.96 | EX14: -64.4267 | EY14: 74.5 | EZ14: 09-27-2025-Sat 13-28-42-PM | FA14: 0 | FB14: 5.964 | FC14: -63.473 | FD14: inf | FE14: 09-27-2025-Sat 13-28-42-PM | FF14: 0.3 | FG14: 5.96 | FH14: -67.7444 | FI14: 24.8333 | FJ14: 09-27-2025-Sat 13-28-42-PM | FK14: 0.2 | FL14: 5.968 | FM14: -64.918 | FN14: 37.3 | FO14: 09-27-2025-Sat 13-28-42-PM | FP14: 0 | FQ14: 5.968 | FR14: -66.1682 | FS14: inf | FT14: 09-27-2025-Sat 13-28-42-PM | FU14: 0 | FV14: 5.964 | FW14: -64.086 | FX14: inf | GD14: 09-27-2025-Sat 13-28-42-PM | GE14: 0.4 | GF14: 5.972 | GG14: -61.2365 | GH14: 18.6625 | GI14: 09-27-2025-Sat 13-28-42-PM | GJ14: 0.2 | GK14: 5.976 | GL14: -62.728 | GM14: 37.35 | GN14: 09-27-2025-Sat 13-28-42-PM | GO14: 0.2 | GP14: 5.972 | GQ14: -62.5196 | GR14: 37.325 | GS14: 09-27-2025-Sat 13-28-42-PM | GT14: 0.5 | GU14: 5.964 | GV14: -64.293 | GW14: 14.91 | HM14: 08-29-2025-Fri 15-33-47-PM | HN14: 0.2 | HO14: 5.904 | HP14: -72.0083 | HQ14: 36.9 | HR14: 08-29-2025-Fri 15-33-47-PM | HS14: 0.2 | HT14: 5.908 | HU14: -71.702 | HV14: 36.925 | HW14: 08-29-2025-Fri 15-33-47-PM | HX14: 0.4 | HY14: 5.912 | HZ14: -71.4511 | IA14: 18.475 | IB14: 08-29-2025-Fri 15-33-47-PM | IC14: 0.3 | ID14: 5.908 | IE14: -70.905 | IF14: 24.6167 | IG14: 08-29-2025-Fri 15-33-47-PM | IH14: -0.3 | II14: 5.9 | IJ14: -70.5987 | IK14: -24.5833 | IL14: 08-29-2025-Fri 15-33-47-PM | IM14: 0.2 | IN14: 5.916 | IO14: -70.959 | IP14: 36.975 | IQ14: 08-29-2025-Fri 15-33-47-PM | IR14: 0.2 | IS14: 5.904 | IT14: -72.336 | IU14: 36.9 | IV14: 08-29-2025-Fri 15-33-47-PM | IW14: 0.2 | IX14: 5.908 | IY14: -71.762 | IZ14: 36.925
A15: 10-24-2025-Fri 18-49-05-PM | B15: 0.1 | C15: 5.848 | D15: -56.1968 | E15: 73.1 | F15: 10-24-2025-Fri 18-49-05-PM | G15: 0 | H15: 5.864 | I15: -53.919 | J15: inf | K15: 10-24-2025-Fri 18-49-05-PM | L15: 0.2 | M15: 5.852 | N15: -56.0978 | O15: 36.575 | P15: 10-24-2025-Fri 18-49-05-PM | Q15: 0.1 | R15: 5.852 | S15: -55.24 | T15: 73.15 | U15: 10-24-2025-Fri 18-49-05-PM | V15: 0.1 | W15: 5.856 | X15: -57.3835 | Y15: 73.2 | Z15: 10-24-2025-Fri 18-49-05-PM | AA15: 0.1 | AB15: 5.856 | AC15: -54.436 | AD15: 73.2 | AE15: 09-12-2025-Fri 12-25-10-PM | AF15: 0.1 | AG15: 5.948 | AH15: -50.7184 | AI15: 74.35 | AJ15: 09-12-2025-Fri 12-25-10-PM | AK15: 0.2 | AL15: 5.96 | AM15: -50.168 | AN15: 37.25 | AO15: 09-12-2025-Fri 12-25-10-PM | AP15: 0.3 | AQ15: 5.948 | AR15: -50.6522 | AS15: 24.7833 | AT15: 09-12-2025-Fri 12-25-10-PM | AU15: 0.1 | AV15: 5.956 | AW15: -50.504 | AX15: 74.45 | AY15: 09-12-2025-Fri 12-25-10-PM | AZ15: 0.5 | BA15: 5.948 | BB15: -52.9968 | BC15: 14.87 | BD15: 09-12-2025-Fri 12-25-10-PM | BE15: 0.4 | BF15: 5.956 | BG15: -51.412 | BH15: 18.6125 | BI15: 09-12-2025-Fri 12-25-10-PM | BJ15: 0.3 | BK15: 5.956 | BL15: -51.412 | BM15: 24.8167 | BN15: 09-12-2025-Fri 12-25-10-PM | BO15: 0.1 | BP15: 5.956 | BQ15: -50.245 | BR15: 74.45 | BS15: 10-24-2025-Fri 18-49-05-PM | BT15: 0.2 | BU15: 5.848 | BV15: -59.0307 | BW15: 36.55 | BX15: 10-24-2025-Fri 18-49-05-PM | BY15: 0.4 | BZ15: 5.856 | CA15: -56.261 | CB15: 18.3 | CM15: 10-24-2025-Fri 18-49-05-PM | CN15: 0.2 | CO15: 5.86 | CP15: -53.314 | CQ15: 36.625 | CR15: 10-24-2025-Fri 18-49-05-PM | CS15: 0.4 | CT15: 5.856 | CU15: -54.3828 | CV15: 18.3 | CW15: 10-24-2025-Fri 18-49-05-PM | CX15: 0.1 | CY15: 5.852 | CZ15: -55.7 | DA15: 73.15 | DB15: 10-24-2025-Fri 18-49-05-PM | DC15: 0.4 | DD15: 5.856 | DE15: -52.3696 | DF15: 18.3 | DL15: 10-24-2025-Fri 18-49-05-PM | DM15: 0.5 | DN15: 5.864 | DO15: -49.7271 | DP15: 14.66 | DQ15: 09-05-2025-Fri 20-16-22-PM | DR15: 0.2 | DS15: 5.904 | DT15: -66.6937 | DU15: 36.9 | DV15: 09-05-2025-Fri 20-16-22-PM | DW15: 0 | DX15: 5.908 | DY15: -65.062 | DZ15: inf | EA15: 09-05-2025-Fri 20-16-22-PM | EB15: -0.1 | EC15: 5.912 | ED15: -65.1497 | EE15: -73.9 | EF15: 09-05-2025-Fri 20-16-22-PM | EG15: 0.1 | EH15: 5.908 | EI15: -63.32 | EJ15: 73.85 | EK15: 09-27-2025-Sat 13-28-44-PM | EL15: 0 | EM15: 5.96 | EN15: -65.6754 | EO15: inf | EP15: 09-27-2025-Sat 13-28-44-PM | EQ15: 0.1 | ER15: 5.976 | ES15: -63.802 | ET15: 74.7 | EU15: 09-27-2025-Sat 13-28-44-PM | EV15: 0.3 | EW15: 5.96 | EX15: -64.4267 | EY15: 24.8333 | EZ15: 09-27-2025-Sat 13-28-44-PM | FA15: 0.2 | FB15: 5.964 | FC15: -63.49 | FD15: 37.275 | FE15: 09-27-2025-Sat 13-28-44-PM | FF15: 0.4 | FG15: 5.964 | FH15: -67.7444 | FI15: 18.6375 | FJ15: 09-27-2025-Sat 13-28-44-PM | FK15: 0.1 | FL15: 5.968 | FM15: -64.918 | FN15: 74.6 | FO15: 09-27-2025-Sat 13-28-44-PM | FP15: 0.1 | FQ15: 5.972 | FR15: -66.1682 | FS15: 74.65 | FT15: 09-27-2025-Sat 13-28-44-PM | FU15: 0.3 | FV15: 5.968 | FW15: -64.13 | FX15: 24.8667 | GD15: 09-27-2025-Sat 13-28-44-PM | GE15: 0.2 | GF15: 5.972 | GG15: -61.3024 | GH15: 37.325 | GI15: 09-27-2025-Sat 13-28-44-PM | GJ15: 0.4 | GK15: 5.968 | GL15: -62.761 | GM15: 18.65 | GN15: 09-27-2025-Sat 13-28-44-PM | GO15: 0.3 | GP15: 5.972 | GQ15: -62.5526 | GR15: 24.8833 | GS15: 09-27-2025-Sat 13-28-44-PM | GT15: 0.5 | GU15: 5.964 | GV15: -64.293 | GW15: 14.91 | HM15: 08-29-2025-Fri 15-33-50-PM | HN15: 0.3 | HO15: 5.904 | HP15: -72.0738 | HQ15: 24.6 | HR15: 08-29-2025-Fri 15-33-50-PM | HS15: 0.1 | HT15: 5.908 | HU15: -71.746 | HV15: 73.85 | HW15: 08-29-2025-Fri 15-33-50-PM | HX15: 0.1 | HY15: 5.912 | HZ15: -71.4839 | IA15: 73.9 | IB15: 08-29-2025-Fri 15-33-50-PM | IC15: 0.2 | ID15: 5.908 | IE15: -70.97 | IF15: 36.925 | IG15: 08-29-2025-Fri 15-33-50-PM | IH15: -0.1 | II15: 5.904 | IJ15: -70.6643 | IK15: -73.8 | IL15: 08-29-2025-Fri 15-33-50-PM | IM15: 0.2 | IN15: 5.916 | IO15: -71.036 | IP15: 36.975 | IQ15: 08-29-2025-Fri 15-33-50-PM | IR15: 0.6 | IS15: 5.904 | IT15: -72.4998 | IU15: 12.3 | IV15: 08-29-2025-Fri 15-33-50-PM | IW15: 0.2 | IX15: 5.908 | IY15: -71.861 | IZ15: 36.925
